Workbook

Sheet 1_METHOD
A1: LOUIS VUITTON — HERITAGE SIGNATURE SCORE
A3: Question
A4: Does the form of a Louis Vuitton object carry the identity of the House on its own, independently of the Monogram and the initials?
A6: Method
A7: Each object is rated on eight visual features, none of which refers to the Monogram or to any logotype. The median profile of objects made between 1854 and 1949 defines the historical reference. Every object is then scored by its distance from that reference: S = 1 means an exact match to the historical profile, S = 0 means maximum deviation.
A9: Two indices are computed. S8 uses all eight features. S6 removes the two ornament features, so that no part of the score can be explained by the Monogram. The comparison between them is the central result.
A11: Validation
A12: Thirty black silhouettes — twenty Louis Vuitton objects and ten control-brand objects — are shown to respondents who are asked only whether each is a Louis Vuitton piece. The score is then correlated against recognition. Control brands are included so that recognition cannot be attributed to familiarity alone.
A14: Three rules fixed in advance
A15: The formula and the eight features were fixed before the survey was run.
A16: Survey objects were selected by their S value across the full range, not by appearance.
A17: Control brands are mandatory; without them the correlation demonstrates nothing.
... A28: Blue headers are entered by hand. Grey headers are computed.

Sheet 2_SCALES
A1: THE EIGHT FEATURES
A2: Rate only what is visible in the image, not what is remembered about the model. None of the eight features refers to the Monogram, the Damier check or any initials — that is the point of the study.
A4: rigidity | B4: Does the object hold its shape when empty?
B5: 1 — fully soft; sags, the contents give it its shape
B6: 2 — soft, with one rigid element such as a base or a batten
B7: 3 — holds its shape, but the walls flex noticeably
B8: 4 — rigid body with soft details such as a flap or pockets
B9: 5 — fully rigid frame on a wooden or fibre base
A12: edge_straightness | B12: How straight are the edges of the body?
B13: 1 — no straight section anywhere in the outline
B14: 2 — curves dominate; one or two straight sections
B15: 3 — straight and curved sections in roughly equal measure
B16: 4 — edges straight, corners noticeably rounded
B17: 5 — all edges straight, corners close to right angles
A20: geometry | B20: Does the outline reduce to a simple figure?
B21: 1 — organic form; does not reduce to a simple figure
B22: 2 — reduces only very approximately
B23: 3 — reduces with noticeable departures
B24: 4 — reduces with slight departures
B25: 5 — outline fully described by a rectangle, trapezoid or cylinder
A28: symmetry | B28: Mirror symmetry about the vertical axis
B29: 1 — clearly asymmetric in the body
B30: 2 — body nearly symmetric, with one large asymmetric element
B31: 3 — body symmetric; hardware and small details are not
B32: 4 — everything symmetric except one detail
B33: 5 — complete mirror symmetry, hardware included
A36: ornament_density | B36: Share of the surface under a repeating pattern
B37: 1 — no pattern, or under 10% of the surface
B38: 2 — pattern covers 10–30%
B39: 3 — pattern covers 30–50%
B40: 4 — pattern covers 50–80%
B41: 5 — pattern covers more than 80% of the surface
A44: ornament_regularity | B44: How strictly periodic the pattern is
B45: 1 — no pattern, or motifs placed without order
B46: 2 — order discernible but frequently broken
B47: 3 — a lattice with deliberate interruptions
B48: 4 — almost strict lattice, isolated exceptions
B49: 5 — strict periodic lattice with no exceptions
A52: hardware | B52: Number of visible metal elements
B53: 1 — no metal elements visible
...

Sheet 3_OBJECTS
A1: CATALOGUED OBJECTS
A2: Blue headers are entered by hand; grey headers are computed. Data begins at row 5. Intermediate arithmetic is held in hidden columns.
A4: obj_id | B4: name | C4: year | D4: decade | E4: source | F4: link | G4: image_file | H4: iconic_model | I4: include | J4: notes | K4: rigidity | L4: edge_straightness | M4: geometry | N4: symmetry | O4: ornament_density | P4: ornament_regularity | Q4: hardware | R4: travel_function | S4: n_rigidity | T4: n_edge_straightness | U4: n_geometry | V4: n_symmetry | W4: n_ornament_density | X4: n_ornament_regularity | Y4: n_hardware | Z4: n_travel_function | AA4: ref_rigidity | AB4: ref_edge_straightness | AC4: ref_geometry | AD4: ref_symmetry | AE4: ref_ornament_density | AF4: ref_ornament_regularity | AG4: ref_hardware | AH4: ref_travel_function | AI4: dev_rigidity | AJ4: dev_edge_straightness | AK4: dev_geometry | AL4: dev_symmetry | AM4: dev_ornament_density | AN4: dev_ornament_regularity | AO4: dev_hardware | AP4: dev_travel_function | AQ4: S8 (all 8) | AR4: in_survey | AS4: type | AT4: S6 (no ornament) | AU4: pre_rigidity | AV4: pre_edge_straightness | AW4: pre_geometry | AX4: pre_symmetry | AY4: pre_ornament_density | AZ4: pre_ornament_regularity | BA4: pre_hardware | BB4: pre_travel_function | BC4: mod_rigidity | BD4: mod_edge_straightness | BE4: mod_geometry | BF4: mod_symmetry | BG4: mod_ornament_density | BH4: mod_ornament_regularity | BI4: mod_hardware | BJ4: mod_travel_function
A5: 1 | B5: A RARE, HERMETIC COPPER EXPLORER WARDROBE TRUNK WITH BRASS HARDWARE | C5: 1925 | D5: =IF(C5="","",FLOOR(C5,10)) -> 1920 | E5: Christie's | F5: https://onlineonly.christies.com/s/legendary-trunks-european-private-collection/rare-hermetic-copper-explorer-wardrobe-trunk-brass-hardware-50/227376 | G5: LV0001.png | H5: no | I5: yes | K5: 5 | L5: 5 | M5: 5 | N5: 5 | O5: 1 | P5: 1 | Q5: 2 | R5: 5 | S5: =IF(K5="","",(K5-1)/4) -> 1 | T5: =IF(L5="","",(L5-1)/4) -> 1 | U5: =IF(M5="","",(M5-1)/4) -> 1 | V5: =IF(N5="","",(N5-1)/4) -> 1 | W5: =IF(O5="","",(O5-1)/4) -> 0 | X5: =IF(P5="","",(P5-1)/4) -> 0 | Y5: =IF(Q5="","",(Q5-1)/4) -> 0.25 | Z5: =IF(R5="","",(R5-1)/4) -> 1 | AA5: =IF(AND(S5<>"",C5<=1949,I5="yes"),S5,"") -> 1 | AB5: =IF(AND(T5<>"",C5<=1949,I5="yes"),T5,"") -> 1 | AC5: =IF(AND(U5<>"",C5<=1949,I5="yes"),U5,"") -> 1 | AD5: =IF(AND(V5<>"",C5<=1949,I5="yes"),V5,"") -> 1 | AE5: =IF(AND(W5<>"",C5<=1949,I5="yes"),W5,"") -> 0 | AF5: =IF(AND(X5<>"",C5<=1949,I5="yes"),X5,"") -> 0 | AG5: =IF(AND(Y5<>"",C5<=1949,I5="yes"),Y5,"") -> 0.25 | AH5: =IF(AND(Z5<>"",C5<=1949,I5="yes"),Z5,"") -> 1 | AI5: =IF(OR(S5="",'4_BENCHMARK'!$C$4=""),"",ABS(S5-'4_BENCHMARK'!$C$4)) -> 0 | AJ5: =IF(OR(T5="",'4_BENCHMARK'!$C$5=""),"",ABS(T5-'4_BENCHMARK'!$C$5)) -> 0 | AK5: =IF(OR(U5="",'4_BENCHMARK'!$C$6=""),"",ABS(U5-'4_BENCHMARK'!$C$6)) -> 0 | AL5: =IF(OR(V5="",'4_BENCHMARK'!$C$7=""),"",ABS(V5-'4_BENCHMARK'!$C$7)) -> 0 | AM5: =IF(OR(W5="",'4_BENCHMARK'!$C$8=""),"",ABS(W5-'4_BENCHMARK'!$C$8)) -> 0 | AN5: =IF(OR(X5="",'4_BENCHMARK'!$C$9=""),"",ABS(X5-'4_BENCHMARK'!$C$9)) -> 0 | AO5: =IF(OR(Y5="",'4_BENCHMARK'!$C$10=""),"",ABS(Y5-'4_BENCHMARK'!$C$10)) -> 0.25 | AP5: =IF(OR(Z5="",'4_BENCHMARK'!$C$11=""),"",ABS(Z5-'4_BENCHMARK'!$C$11)) -> 0 | AQ5: =IF(COUNT(AI5:AP5)<8,"",1-AVERAGE(AI5:AP5)) -> 0.96875 | AS5: trunk | AT5: =IF(COUNT(AI5:AL5,AO5:AP5)<6,"",1-AVERAGE(AI5:AL5,AO5:AP5)) -> 0.95833333 | AU5: =IF(AND($I5="yes",$C5<=1949,K5<>""),K5,"") -> 5 | AV5: =IF(AND($I5="yes",$C5<=1949,L5<>""),L5,"") -> 5 | AW5: =IF(AND($I5="yes",$C5<=1949,M5<>""),M5,"") -> 5 | AX5: =IF(AND($I5="yes",$C5<=1949,N5<>""),N5,"") -> 5 | AY5: =IF(AND($I5="yes",$C5<=1949,O5<>""),O5,"") -> 1 | AZ5: =IF(AND($I5="yes",$C5<=1949,P5<>""),P5,"") -> 1 | BA5: =IF(AND($I5="yes",$C5<=1949,Q5<>""),Q5,"") -> 2 | BB5: =IF(AND($I5="yes",$C5<=1949,R5<>""),R5,"") -> 5 | BC5: =IF(AND($I5="yes",$C5>=2000,K5<>""),K5,"") | BD5: =IF(AND($I5="yes",$C5>=2000,L5<>""),L5,"") | BE5: =IF(AND($I5="yes",$C5>=2000,M5<>""),M5,"") | BF5: =IF(AND($I5="yes",$C5>=2000,N5<>""),N5,"") | BG5: =IF(AND($I5="yes",$C5>=2000,O5<>""),O5,"") | BH5: =IF(AND($I5="yes",$C5>=2000,P5<>""),P5,"") | BI5: =IF(AND($I5="yes",$C5>=2000,Q5<>""),Q5,"") | BJ5: =IF(AND($I5="yes",$C5>=2000,R5<>""),R5,"")
A6: 2 | B6: A RARE, LIMITED EDITION YELLOW & BLACK MONOGRAM LEATHER PUMPKIN BAG WITH SILVER HARDWARE BY YAYOI KUSAMA | C6: 2023 | D6: =IF(C6="","",FLOOR(C6,10)) -> 2020 | E6: Christie's | F6: https://onlineonly.christies.com/s/handbags-online-september-edition/rare-limited-edition-yellow-black-monogram-leather-pumpkin-bag-silver-60/231632 | G6: LV0002.png | H6: yes | I6: yes | K6: 3 | L6: 2 | M6: 3 | N6: 4 | O6: 4 | P6: 5 | Q6: 3 | R6: 3 | S6: =IF(K6="","",(K6-1)/4) -> 0.5 | T6: =IF(L6="","",(L6-1)/4) -> 0.25 | U6: =IF(M6="","",(M6-1)/4) -> 0.5 | V6: =IF(N6="","",(N6-1)/4) -> 0.75 | W6: =IF(O6="","",(O6-1)/4) -> 0.75 | X6: =IF(P6="","",(P6-1)/4) -> 1 | Y6: =IF(Q6="","",(Q6-1)/4) -> 0.5 | Z6: =IF(R6="","",(R6-1)/4) -> 0.5 | AA6: =IF(AND(S6<>"",C6<=1949,I6="yes"),S6,"") | AB6: =IF(AND(T6<>"",C6<=1949,I6="yes"),T6,"") | AC6: =IF(AND(U6<>"",C6<=1949,I6="yes"),U6,"") | AD6: =IF(AND(V6<>"",C6<=1949,I6="yes"),V6,"") | AE6: =IF(AND(W6<>"",C6<=1949,I6="yes"),W6,"") | AF6: =IF(AND(X6<>"",C6<=1949,I6="yes"),X6,"") | AG6: =IF(AND(Y6<>"",C6<=1949,I6="yes"),Y6,"") | AH6: =IF(AND(Z6<>"",C6<=1949,I6="yes"),Z6,"") | AI6: =IF(OR(S6="",'4_BENCHMARK'!$C$4=""),"",ABS(S6-'4_BENCHMARK'!$C$4)) -> 0.5 | AJ6: =IF(OR(T6="",'4_BENCHMARK'!$C$5=""),"",ABS(T6-'4_BENCHMARK'!$C$5)) -> 0.75 | AK6: =IF(OR(U6="",'4_BENCHMARK'!$C$6=""),"",ABS(U6-'4_BENCHMARK'!$C$6)) -> 0.5 | AL6: =IF(OR(V6="",'4_BENCHMARK'!$C$7=""),"",ABS(V6-'4_BENCHMARK'!$C$7)) -> 0.25 | AM6: =IF(OR(W6="",'4_BENCHMARK'!$C$8=""),"",ABS(W6-'4_BENCHMARK'!$C$8)) -> 0.75 | AN6: =IF(OR(X6="",'4_BENCHMARK'!$C$9=""),"",ABS(X6-'4_BENCHMARK'!$C$9)) -> 1 | AO6: =IF(OR(Y6="",'4_BENCHMARK'!$C$10=""),"",ABS(Y6-'4_BENCHMARK'!$C$10)) -> 0 | AP6: =IF(OR(Z6="",'4_BENCHMARK'!$C$11=""),"",ABS(Z6-'4_BENCHMARK'!$C$11)) -> 0.5 | AQ6: =IF(COUNT(AI6:AP6)<8,"",1-AVERAGE(AI6:AP6)) -> 0.46875 | AS6: bag | AT6: =IF(COUNT(AI6:AL6,AO6:AP6)<6,"",1-AVERAGE(AI6:AL6,AO6:AP6)) -> 0.58333333 | AU6: =IF(AND($I6="yes",$C6<=1949,K6<>""),K6,"") | AV6: =IF(AND($I6="yes",$C6<=1949,L6<>""),L6,"") | AW6: =IF(AND($I6="yes",$C6<=1949,M6<>""),M6,"") | AX6: =IF(AND($I6="yes",$C6<=1949,N6<>""),N6,"") | AY6: =IF(AND($I6="yes",$C6<=1949,O6<>""),O6,"") | AZ6: =IF(AND($I6="yes",$C6<=1949,P6<>""),P6,"") | BA6: =IF(AND($I6="yes",$C6<=1949,Q6<>""),Q6,"") | BB6: =IF(AND($I6="yes",$C6<=1949,R6<>""),R6,"") | BC6: =IF(AND($I6="yes",$C6>=2000,K6<>""),K6,"") -> 3 | BD6: =IF(AND($I6="yes",$C6>=2000,L6<>""),L6,"") -> 2 | BE6: =IF(AND($I6="yes",$C6>=2000,M6<>""),M6,"") -> 3 | BF6: =IF(AND($I6="yes",$C6>=2000,N6<>""),N6,"") -> 4 | BG6: =IF(AND($I6="yes",$C6>=2000,O6<>""),O6,"") -> 4 | BH6: =IF(AND($I6="yes",$C6>=2000,P6<>""),P6,"") -> 5 | BI6: =IF(AND($I6="yes",$C6>=2000,Q6<>""),Q6,"") -> 3 | BJ6: =IF(AND($I6="yes",$C6>=2000,R6<>""),R6,"") -> 3
A7: 3 | B7: A RARE, HERMETIC COPPER RIFLE TRUNK WITH BRASS HARDWARE | C7: 1896 | D7: =IF(C7="","",FLOOR(C7,10)) -> 1890 | E7: Christie's | F7: https://onlineonly.christies.com/s/legendary-trunks-european-private-collection/rare-hermetic-copper-rifle-trunk-brass-hardware-45/227574 | G7: LV0003.png | H7: no | I7: yes | K7: 5 | L7: 5 | M7: 5 | N7: 5 | O7: 1 | P7: 1 | Q7: 3 | R7: 5 | S7: =IF(K7="","",(K7-1)/4) -> 1 | T7: =IF(L7="","",(L7-1)/4) -> 1 | U7: =IF(M7="","",(M7-1)/4) -> 1 | V7: =IF(N7="","",(N7-1)/4) -> 1 | W7: =IF(O7="","",(O7-1)/4) -> 0 | X7: =IF(P7="","",(P7-1)/4) -> 0 | Y7: =IF(Q7="","",(Q7-1)/4) -> 0.5 | Z7: =IF(R7="","",(R7-1)/4) -> 1 | AA7: =IF(AND(S7<>"",C7<=1949,I7="yes"),S7,"") -> 1 | AB7: =IF(AND(T7<>"",C7<=1949,I7="yes"),T7,"") -> 1 | AC7: =IF(AND(U7<>"",C7<=1949,I7="yes"),U7,"") -> 1 | AD7: =IF(AND(V7<>"",C7<=1949,I7="yes"),V7,"") -> 1 | AE7: =IF(AND(W7<>"",C7<=1949,I7="yes"),W7,"") -> 0 | AF7: =IF(AND(X7<>"",C7<=1949,I7="yes"),X7,"") -> 0 | AG7: =IF(AND(Y7<>"",C7<=1949,I7="yes"),Y7,"") -> 0.5 | AH7: =IF(AND(Z7<>"",C7<=1949,I7="yes"),Z7,"") -> 1 | AI7: =IF(OR(S7="",'4_BENCHMARK'!$C$4=""),"",ABS(S7-'4_BENCHMARK'!$C$4)) -> 0 | AJ7: =IF(OR(T7="",'4_BENCHMARK'!$C$5=""),"",ABS(T7-'4_BENCHMARK'!$C$5)) -> 0 | AK7: =IF(OR(U7="",'4_BENCHMARK'!$C$6=""),"",ABS(U7-'4_BENCHMARK'!$C$6)) -> 0 | AL7: =IF(OR(V7="",'4_BENCHMARK'!$C$7=""),"",ABS(V7-'4_BENCHMARK'!$C$7)) -> 0 | AM7: =IF(OR(W7="",'4_BENCHMARK'!$C$8=""),"",ABS(W7-'4_BENCHMARK'!$C$8)) -> 0 | AN7: =IF(OR(X7="",'4_BENCHMARK'!$C$9=""),"",ABS(X7-'4_BENCHMARK'!$C$9)) -> 0 | AO7: =IF(OR(Y7="",'4_BENCHMARK'!$C$10=""),"",ABS(Y7-'4_BENCHMARK'!$C$10)) -> 0 | AP7: =IF(OR(Z7="",'4_BENCHMARK'!$C$11=""),"",ABS(Z7-'4_BENCHMARK'!$C$11)) -> 0 | AQ7: =IF(COUNT(AI7:AP7)<8,"",1-AVERAGE(AI7:AP7)) -> 1 | AS7: suitcase | AT7: =IF(COUNT(AI7:AL7,AO7:AP7)<6,"",1-AVERAGE(AI7:AL7,AO7:AP7)) -> 1 | AU7: =IF(AND($I7="yes",$C7<=1949,K7<>""),K7,"") -> 5 | AV7: =IF(AND($I7="yes",$C7<=1949,L7<>""),L7,"") -> 5 | AW7: =IF(AND($I7="yes",$C7<=1949,M7<>""),M7,"") -> 5 | AX7: =IF(AND($I7="yes",$C7<=1949,N7<>""),N7,"") -> 5 | AY7: =IF(AND($I7="yes",$C7<=1949,O7<>""),O7,"") -> 1 | AZ7: =IF(AND($I7="yes",$C7<=1949,P7<>""),P7,"") -> 1 | BA7: =IF(AND($I7="yes",$C7<=1949,Q7<>""),Q7,"") -> 3 | BB7: =IF(AND($I7="yes",$C7<=1949,R7<>""),R7,"") -> 5 | BC7: =IF(AND($I7="yes",$C7>=2000,K7<>""),K7,"") | BD7: =IF(AND($I7="yes",$C7>=2000,L7<>""),L7,"") | BE7: =IF(AND($I7="yes",$C7>=2000,M7<>""),M7,"") | BF7: =IF(AND($I7="yes",$C7>=2000,N7<>""),N7,"") | BG7: =IF(AND($I7="yes",$C7>=2000,O7<>""),O7,"") | BH7: =IF(AND($I7="yes",$C7>=2000,P7<>""),P7,"") | BI7: =IF(AND($I7="yes",$C7>=2000,Q7<>""),Q7,"") | BJ7: =IF(AND($I7="yes",$C7>=2000,R7<>""),R7,"")
A8: 4 | B8: A RARE, CLASSIC MONOGRAM HIGH TEA TRUNK WITH BRASS HARDWARE | C8: 2025 | D8: =IF(C8="","",FLOOR(C8,10)) -> 2020 | E8: Christie's | F8: https://www.christies.com/en/lot/lot-6586998 | G8: LV0004.png | H8: yes | I8: yes | K8: 5 | L8: 5 | M8: 5 | N8: 5 | O8: 5 | P8: 5 | Q8: 2 | R8: 5 | S8: =IF(K8="","",(K8-1)/4) -> 1 | T8: =IF(L8="","",(L8-1)/4) -> 1 | U8: =IF(M8="","",(M8-1)/4) -> 1 | V8: =IF(N8="","",(N8-1)/4) -> 1 | W8: =IF(O8="","",(O8-1)/4) -> 1 | X8: =IF(P8="","",(P8-1)/4) -> 1 | Y8: =IF(Q8="","",(Q8-1)/4) -> 0.25 | Z8: =IF(R8="","",(R8-1)/4) -> 1 | AA8: =IF(AND(S8<>"",C8<=1949,I8="yes"),S8,"") | AB8: =IF(AND(T8<>"",C8<=1949,I8="yes"),T8,"") | AC8: =IF(AND(U8<>"",C8<=1949,I8="yes"),U8,"") | AD8: =IF(AND(V8<>"",C8<=1949,I8="yes"),V8,"") | AE8: =IF(AND(W8<>"",C8<=1949,I8="yes"),W8,"") | AF8: =IF(AND(X8<>"",C8<=1949,I8="yes"),X8,"") | AG8: =IF(AND(Y8<>"",C8<=1949,I8="yes"),Y8,"") | AH8: =IF(AND(Z8<>"",C8<=1949,I8="yes"),Z8,"") | AI8: =IF(OR(S8="",'4_BENCHMARK'!$C$4=""),"",ABS(S8-'4_BENCHMARK'!$C$4)) -> 0 | AJ8: =IF(OR(T8="",'4_BENCHMARK'!$C$5=""),"",ABS(T8-'4_BENCHMARK'!$C$5)) -> 0 | AK8: =IF(OR(U8="",'4_BENCHMARK'!$C$6=""),"",ABS(U8-'4_BENCHMARK'!$C$6)) -> 0 | AL8: =IF(OR(V8="",'4_BENCHMARK'!$C$7=""),"",ABS(V8-'4_BENCHMARK'!$C$7)) -> 0 | AM8: =IF(OR(W8="",'4_BENCHMARK'!$C$8=""),"",ABS(W8-'4_BENCHMARK'!$C$8)) -> 1 | AN8: =IF(OR(X8="",'4_BENCHMARK'!$C$9=""),"",ABS(X8-'4_BENCHMARK'!$C$9)) -> 1 | AO8: =IF(OR(Y8="",'4_BENCHMARK'!$C$10=""),"",ABS(Y8-'4_BENCHMARK'!$C$10)) -> 0.25 | AP8: =IF(OR(Z8="",'4_BENCHMARK'!$C$11=""),"",ABS(Z8-'4_BENCHMARK'!$C$11)) -> 0 | AQ8: =IF(COUNT(AI8:AP8)<8,"",1-AVERAGE(AI8:AP8)) -> 0.71875 | AS8: trunk | AT8: =IF(COUNT(AI8:AL8,AO8:AP8)<6,"",1-AVERAGE(AI8:AL8,AO8:AP8)) -> 0.95833333 | AU8: =IF(AND($I8="yes",$C8<=1949,K8<>""),K8,"") | AV8: =IF(AND($I8="yes",$C8<=1949,L8<>""),L8,"") | AW8: =IF(AND($I8="yes",$C8<=1949,M8<>""),M8,"") | AX8: =IF(AND($I8="yes",$C8<=1949,N8<>""),N8,"") | AY8: =IF(AND($I8="yes",$C8<=1949,O8<>""),O8,"") | AZ8: =IF(AND($I8="yes",$C8<=1949,P8<>""),P8,"") | BA8: =IF(AND($I8="yes",$C8<=1949,Q8<>""),Q8,"") | BB8: =IF(AND($I8="yes",$C8<=1949,R8<>""),R8,"") | BC8: =IF(AND($I8="yes",$C8>=2000,K8<>""),K8,"") -> 5 | BD8: =IF(AND($I8="yes",$C8>=2000,L8<>""),L8,"") -> 5 | BE8: =IF(AND($I8="yes",$C8>=2000,M8<>""),M8,"") -> 5 | BF8: =IF(AND($I8="yes",$C8>=2000,N8<>""),N8,"") -> 5 | BG8: =IF(AND($I8="yes",$C8>=2000,O8<>""),O8,"") -> 5 | BH8: =IF(AND($I8="yes",$C8>=2000,P8<>""),P8,"") -> 5 | BI8: =IF(AND($I8="yes",$C8>=2000,Q8<>""),Q8,"") -> 2 | BJ8: =IF(AND($I8="yes",$C8>=2000,R8<>""),R8,"") -> 5
A9: 5 | B9: A RARE, ALUMINIUM EXPLORER TRUNK | C9: 1892 | D9: =IF(C9="","",FLOOR(C9,10)) -> 1890 | E9: Christie's | F9: https://www.christies.com/en/lot/lot-6177673 | G9: LV0005.png | H9: no | I9: yes | K9: 5 | L9: 5 | M9: 5 | N9: 5 | O9: 1 | P9: 1 | Q9: 5 | R9: 5 | S9: =IF(K9="","",(K9-1)/4) -> 1 | T9: =IF(L9="","",(L9-1)/4) -> 1 | U9: =IF(M9="","",(M9-1)/4) -> 1 | V9: =IF(N9="","",(N9-1)/4) -> 1 | W9: =IF(O9="","",(O9-1)/4) -> 0 | X9: =IF(P9="","",(P9-1)/4) -> 0 | Y9: =IF(Q9="","",(Q9-1)/4) -> 1 | Z9: =IF(R9="","",(R9-1)/4) -> 1 | AA9: =IF(AND(S9<>"",C9<=1949,I9="yes"),S9,"") -> 1 | AB9: =IF(AND(T9<>"",C9<=1949,I9="yes"),T9,"") -> 1 | AC9: =IF(AND(U9<>"",C9<=1949,I9="yes"),U9,"") -> 1 | AD9: =IF(AND(V9<>"",C9<=1949,I9="yes"),V9,"") -> 1 | AE9: =IF(AND(W9<>"",C9<=1949,I9="yes"),W9,"") -> 0 | AF9: =IF(AND(X9<>"",C9<=1949,I9="yes"),X9,"") -> 0 | AG9: =IF(AND(Y9<>"",C9<=1949,I9="yes"),Y9,"") -> 1 | AH9: =IF(AND(Z9<>"",C9<=1949,I9="yes"),Z9,"") -> 1 | AI9: =IF(OR(S9="",'4_BENCHMARK'!$C$4=""),"",ABS(S9-'4_BENCHMARK'!$C$4)) -> 0 | AJ9: =IF(OR(T9="",'4_BENCHMARK'!$C$5=""),"",ABS(T9-'4_BENCHMARK'!$C$5)) -> 0 | AK9: =IF(OR(U9="",'4_BENCHMARK'!$C$6=""),"",ABS(U9-'4_BENCHMARK'!$C$6)) -> 0 | AL9: =IF(OR(V9="",'4_BENCHMARK'!$C$7=""),"",ABS(V9-'4_BENCHMARK'!$C$7)) -> 0 | AM9: =IF(OR(W9="",'4_BENCHMARK'!$C$8=""),"",ABS(W9-'4_BENCHMARK'!$C$8)) -> 0 | AN9: =IF(OR(X9="",'4_BENCHMARK'!$C$9=""),"",ABS(X9-'4_BENCHMARK'!$C$9)) -> 0 | AO9: =IF(OR(Y9="",'4_BENCHMARK'!$C$10=""),"",ABS(Y9-'4_BENCHMARK'!$C$10)) -> 0.5 | AP9: =IF(OR(Z9="",'4_BENCHMARK'!$C$11=""),"",ABS(Z9-'4_BENCHMARK'!$C$11)) -> 0 | AQ9: =IF(COUNT(AI9:AP9)<8,"",1-AVERAGE(AI9:AP9)) -> 0.9375 | AS9: trunk | AT9: =IF(COUNT(AI9:AL9,AO9:AP9)<6,"",1-AVERAGE(AI9:AL9,AO9:AP9)) -> 0.91666667 | AU9: =IF(AND($I9="yes",$C9<=1949,K9<>""),K9,"") -> 5 | AV9: =IF(AND($I9="yes",$C9<=1949,L9<>""),L9,"") -> 5 | AW9: =IF(AND($I9="yes",$C9<=1949,M9<>""),M9,"") -> 5 | AX9: =IF(AND($I9="yes",$C9<=1949,N9<>""),N9,"") -> 5 | AY9: =IF(AND($I9="yes",$C9<=1949,O9<>""),O9,"") -> 1 | AZ9: =IF(AND($I9="yes",$C9<=1949,P9<>""),P9,"") -> 1 | BA9: =IF(AND($I9="yes",$C9<=1949,Q9<>""),Q9,"") -> 5 | BB9: =IF(AND($I9="yes",$C9<=1949,R9<>""),R9,"") -> 5 | BC9: =IF(AND($I9="yes",$C9>=2000,K9<>""),K9,"") | BD9: =IF(AND($I9="yes",$C9>=2000,L9<>""),L9,"") | BE9: =IF(AND($I9="yes",$C9>=2000,M9<>""),M9,"") | BF9: =IF(AND($I9="yes",$C9>=2000,N9<>""),N9,"") | BG9: =IF(AND($I9="yes",$C9>=2000,O9<>""),O9,"") | BH9: =IF(AND($I9="yes",$C9>=2000,P9<>""),P9,"") | BI9: =IF(AND($I9="yes",$C9>=2000,Q9<>""),Q9,"") | BJ9: =IF(AND($I9="yes",$C9>=2000,R9<>""),R9,"")
A10: 6 | B10: A LIMITED EDITION RED & WHITE MONOGRAM MALLE COURRIER 90 TRUNK WITH SILVER HARDWARE BY SUPREME | C10: 2017 | D10: =IF(C10="","",FLOOR(C10,10)) -> 2010 | E10: Christie's | F10: https://www.christies.com/en/lot/lot-6205936 | G10: LV0006.png | H10: yes | I10: yes | K10: 5 | L10: 5 | M10: 5 | N10: 4 | O10: 5 | P10: 3 | Q10: 4 | R10: 5 | S10: =IF(K10="","",(K10-1)/4) -> 1 | T10: =IF(L10="","",(L10-1)/4) -> 1 | U10: =IF(M10="","",(M10-1)/4) -> 1 | V10: =IF(N10="","",(N10-1)/4) -> 0.75 | W10: =IF(O10="","",(O10-1)/4) -> 1 | X10: =IF(P10="","",(P10-1)/4) -> 0.5 | Y10: =IF(Q10="","",(Q10-1)/4) -> 0.75 | Z10: =IF(R10="","",(R10-1)/4) -> 1 | AA10: =IF(AND(S10<>"",C10<=1949,I10="yes"),S10,"") | AB10: =IF(AND(T10<>"",C10<=1949,I10="yes"),T10,"") | AC10: =IF(AND(U10<>"",C10<=1949,I10="yes"),U10,"") | AD10: =IF(AND(V10<>"",C10<=1949,I10="yes"),V10,"") | AE10: =IF(AND(W10<>"",C10<=1949,I10="yes"),W10,"") | AF10: =IF(AND(X10<>"",C10<=1949,I10="yes"),X10,"") | AG10: =IF(AND(Y10<>"",C10<=1949,I10="yes"),Y10,"") | AH10: =IF(AND(Z10<>"",C10<=1949,I10="yes"),Z10,"") | AI10: =IF(OR(S10="",'4_BENCHMARK'!$C$4=""),"",ABS(S10-'4_BENCHMARK'!$C$4)) -> 0 | AJ10: =IF(OR(T10="",'4_BENCHMARK'!$C$5=""),"",ABS(T10-'4_BENCHMARK'!$C$5)) -> 0 | AK10: =IF(OR(U10="",'4_BENCHMARK'!$C$6=""),"",ABS(U10-'4_BENCHMARK'!$C$6)) -> 0 | AL10: =IF(OR(V10="",'4_BENCHMARK'!$C$7=""),"",ABS(V10-'4_BENCHMARK'!$C$7)) -> 0.25 | AM10: =IF(OR(W10="",'4_BENCHMARK'!$C$8=""),"",ABS(W10-'4_BENCHMARK'!$C$8)) -> 1 | AN10: =IF(OR(X10="",'4_BENCHMARK'!$C$9=""),"",ABS(X10-'4_BENCHMARK'!$C$9)) -> 0.5 | AO10: =IF(OR(Y10="",'4_BENCHMARK'!$C$10=""),"",ABS(Y10-'4_BENCHMARK'!$C$10)) -> 0.25 | AP10: =IF(OR(Z10="",'4_BENCHMARK'!$C$11=""),"",ABS(Z10-'4_BENCHMARK'!$C$11)) -> 0 | AQ10: =IF(COUNT(AI10:AP10)<8,"",1-AVERAGE(AI10:AP10)) -> 0.75 | AS10: trunk | AT10: =IF(COUNT(AI10:AL10,AO10:AP10)<6,"",1-AVERAGE(AI10:AL10,AO10:AP10)) -> 0.91666667 | AU10: =IF(AND($I10="yes",$C10<=1949,K10<>""),K10,"") | AV10: =IF(AND($I10="yes",$C10<=1949,L10<>""),L10,"") | AW10: =IF(AND($I10="yes",$C10<=1949,M10<>""),M10,"") | AX10: =IF(AND($I10="yes",$C10<=1949,N10<>""),N10,"") | AY10: =IF(AND($I10="yes",$C10<=1949,O10<>""),O10,"") | AZ10: =IF(AND($I10="yes",$C10<=1949,P10<>""),P10,"") | BA10: =IF(AND($I10="yes",$C10<=1949,Q10<>""),Q10,"") | BB10: =IF(AND($I10="yes",$C10<=1949,R10<>""),R10,"") | BC10: =IF(AND($I10="yes",$C10>=2000,K10<>""),K10,"") -> 5 | BD10: =IF(AND($I10="yes",$C10>=2000,L10<>""),L10,"") -> 5 | BE10: =IF(AND($I10="yes",$C10>=2000,M10<>""),M10,"") -> 5 | BF10: =IF(AND($I10="yes",$C10>=2000,N10<>""),N10,"") -> 4 | BG10: =IF(AND($I10="yes",$C10>=2000,O10<>""),O10,"") -> 5 | BH10: =IF(AND($I10="yes",$C10>=2000,P10<>""),P10,"") -> 3 | BI10: =IF(AND($I10="yes",$C10>=2000,Q10<>""),Q10,"") -> 4 | BJ10: =IF(AND($I10="yes",$C10>=2000,R10<>""),R10,"") -> 5
A11: 7 | B11: A RARE, HERMETIC ZINC EXPLORER TRUNK WITH BRASS HARDWARE | C11: 1890 | D11: =IF(C11="","",FLOOR(C11,10)) -> 1890 | E11: Christie's | F11: https://onlineonly.christies.com/s/legendary-trunks-european-private-collection-part-ii/rare-hermetic-zinc-explorer-trunk-brass-hardware-38/262989 | G11: LV0007.png | H11: no | I11: yes | K11: 5 | L11: 5 | M11: 5 | N11: 5 | O11: 1 | P11: 1 | Q11: 5 | R11: 5 | S11: =IF(K11="","",(K11-1)/4) -> 1 | T11: =IF(L11="","",(L11-1)/4) -> 1 | U11: =IF(M11="","",(M11-1)/4) -> 1 | V11: =IF(N11="","",(N11-1)/4) -> 1 | W11: =IF(O11="","",(O11-1)/4) -> 0 | X11: =IF(P11="","",(P11-1)/4) -> 0 | Y11: =IF(Q11="","",(Q11-1)/4) -> 1 | Z11: =IF(R11="","",(R11-1)/4) -> 1 | AA11: =IF(AND(S11<>"",C11<=1949,I11="yes"),S11,"") -> 1 | AB11: =IF(AND(T11<>"",C11<=1949,I11="yes"),T11,"") -> 1 | AC11: =IF(AND(U11<>"",C11<=1949,I11="yes"),U11,"") -> 1 | AD11: =IF(AND(V11<>"",C11<=1949,I11="yes"),V11,"") -> 1 | AE11: =IF(AND(W11<>"",C11<=1949,I11="yes"),W11,"") -> 0 | AF11: =IF(AND(X11<>"",C11<=1949,I11="yes"),X11,"") -> 0 | AG11: =IF(AND(Y11<>"",C11<=1949,I11="yes"),Y11,"") -> 1 | AH11: =IF(AND(Z11<>"",C11<=1949,I11="yes"),Z11,"") -> 1 | AI11: =IF(OR(S11="",'4_BENCHMARK'!$C$4=""),"",ABS(S11-'4_BENCHMARK'!$C$4)) -> 0 | AJ11: =IF(OR(T11="",'4_BENCHMARK'!$C$5=""),"",ABS(T11-'4_BENCHMARK'!$C$5)) -> 0 | AK11: =IF(OR(U11="",'4_BENCHMARK'!$C$6=""),"",ABS(U11-'4_BENCHMARK'!$C$6)) -> 0 | AL11: =IF(OR(V11="",'4_BENCHMARK'!$C$7=""),"",ABS(V11-'4_BENCHMARK'!$C$7)) -> 0 | AM11: =IF(OR(W11="",'4_BENCHMARK'!$C$8=""),"",ABS(W11-'4_BENCHMARK'!$C$8)) -> 0 | AN11: =IF(OR(X11="",'4_BENCHMARK'!$C$9=""),"",ABS(X11-'4_BENCHMARK'!$C$9)) -> 0 | AO11: =IF(OR(Y11="",'4_BENCHMARK'!$C$10=""),"",ABS(Y11-'4_BENCHMARK'!$C$10)) -> 0.5 | AP11: =IF(OR(Z11="",'4_BENCHMARK'!$C$11=""),"",ABS(Z11-'4_BENCHMARK'!$C$11)) -> 0 | AQ11: =IF(COUNT(AI11:AP11)<8,"",1-AVERAGE(AI11:AP11)) -> 0.9375 | AS11: trunk | AT11: =IF(COUNT(AI11:AL11,AO11:AP11)<6,"",1-AVERAGE(AI11:AL11,AO11:AP11)) -> 0.91666667 | AU11: =IF(AND($I11="yes",$C11<=1949,K11<>""),K11,"") -> 5 | AV11: =IF(AND($I11="yes",$C11<=1949,L11<>""),L11,"") -> 5 | AW11: =IF(AND($I11="yes",$C11<=1949,M11<>""),M11,"") -> 5 | AX11: =IF(AND($I11="yes",$C11<=1949,N11<>""),N11,"") -> 5 | AY11: =IF(AND($I11="yes",$C11<=1949,O11<>""),O11,"") -> 1 | AZ11: =IF(AND($I11="yes",$C11<=1949,P11<>""),P11,"") -> 1 | BA11: =IF(AND($I11="yes",$C11<=1949,Q11<>""),Q11,"") -> 5 | BB11: =IF(AND($I11="yes",$C11<=1949,R11<>""),R11,"") -> 5 | BC11: =IF(AND($I11="yes",$C11>=2000,K11<>""),K11,"") | BD11: =IF(AND($I11="yes",$C11>=2000,L11<>""),L11,"") | BE11: =IF(AND($I11="yes",$C11>=2000,M11<>""),M11,"") | BF11: =IF(AND($I11="yes",$C11>=2000,N11<>""),N11,"") | BG11: =IF(AND($I11="yes",$C11>=2000,O11<>""),O11,"") | BH11: =IF(AND($I11="yes",$C11>=2000,P11<>""),P11,"") | BI11: =IF(AND($I11="yes",$C11>=2000,Q11<>""),Q11,"") | BJ11: =IF(AND($I11="yes",$C11>=2000,R11<>""),R11,"")
A12: 8 | B12: A RARE, BRASS EXPLORER TRUNK | C12: 1888 | D12: =IF(C12="","",FLOOR(C12,10)) -> 1880 | E12: Christie's | F12: https://www.christies.com/en/lot/lot-6205939 | G12: LV0008.png | H12: no | I12: yes | K12: 5 | L12: 5 | M12: 5 | N12: 5 | O12: 1 | P12: 1 | Q12: 5 | R12: 5 | S12: =IF(K12="","",(K12-1)/4) -> 1 | T12: =IF(L12="","",(L12-1)/4) -> 1 | U12: =IF(M12="","",(M12-1)/4) -> 1 | V12: =IF(N12="","",(N12-1)/4) -> 1 | W12: =IF(O12="","",(O12-1)/4) -> 0 | X12: =IF(P12="","",(P12-1)/4) -> 0 | Y12: =IF(Q12="","",(Q12-1)/4) -> 1 | Z12: =IF(R12="","",(R12-1)/4) -> 1 | AA12: =IF(AND(S12<>"",C12<=1949,I12="yes"),S12,"") -> 1 | AB12: =IF(AND(T12<>"",C12<=1949,I12="yes"),T12,"") -> 1 | AC12: =IF(AND(U12<>"",C12<=1949,I12="yes"),U12,"") -> 1 | AD12: =IF(AND(V12<>"",C12<=1949,I12="yes"),V12,"") -> 1 | AE12: =IF(AND(W12<>"",C12<=1949,I12="yes"),W12,"") -> 0 | AF12: =IF(AND(X12<>"",C12<=1949,I12="yes"),X12,"") -> 0 | AG12: =IF(AND(Y12<>"",C12<=1949,I12="yes"),Y12,"") -> 1 | AH12: =IF(AND(Z12<>"",C12<=1949,I12="yes"),Z12,"") -> 1 | AI12: =IF(OR(S12="",'4_BENCHMARK'!$C$4=""),"",ABS(S12-'4_BENCHMARK'!$C$4)) -> 0 | AJ12: =IF(OR(T12="",'4_BENCHMARK'!$C$5=""),"",ABS(T12-'4_BENCHMARK'!$C$5)) -> 0 | AK12: =IF(OR(U12="",'4_BENCHMARK'!$C$6=""),"",ABS(U12-'4_BENCHMARK'!$C$6)) -> 0 | AL12: =IF(OR(V12="",'4_BENCHMARK'!$C$7=""),"",ABS(V12-'4_BENCHMARK'!$C$7)) -> 0 | AM12: =IF(OR(W12="",'4_BENCHMARK'!$C$8=""),"",ABS(W12-'4_BENCHMARK'!$C$8)) -> 0 | AN12: =IF(OR(X12="",'4_BENCHMARK'!$C$9=""),"",ABS(X12-'4_BENCHMARK'!$C$9)) -> 0 | AO12: =IF(OR(Y12="",'4_BENCHMARK'!$C$10=""),"",ABS(Y12-'4_BENCHMARK'!$C$10)) -> 0.5 | AP12: =IF(OR(Z12="",'4_BENCHMARK'!$C$11=""),"",ABS(Z12-'4_BENCHMARK'!$C$11)) -> 0 | AQ12: =IF(COUNT(AI12:AP12)<8,"",1-AVERAGE(AI12:AP12)) -> 0.9375 | AS12: trunk | AT12: =IF(COUNT(AI12:AL12,AO12:AP12)<6,"",1-AVERAGE(AI12:AL12,AO12:AP12)) -> 0.91666667 | AU12: =IF(AND($I12="yes",$C12<=1949,K12<>""),K12,"") -> 5 | AV12: =IF(AND($I12="yes",$C12<=1949,L12<>""),L12,"") -> 5 | AW12: =IF(AND($I12="yes",$C12<=1949,M12<>""),M12,"") -> 5 | AX12: =IF(AND($I12="yes",$C12<=1949,N12<>""),N12,"") -> 5 | AY12: =IF(AND($I12="yes",$C12<=1949,O12<>""),O12,"") -> 1 | AZ12: =IF(AND($I12="yes",$C12<=1949,P12<>""),P12,"") -> 1 | BA12: =IF(AND($I12="yes",$C12<=1949,Q12<>""),Q12,"") -> 5 | BB12: =IF(AND($I12="yes",$C12<=1949,R12<>""),R12,"") -> 5 | BC12: =IF(AND($I12="yes",$C12>=2000,K12<>""),K12,"") | BD12: =IF(AND($I12="yes",$C12>=2000,L12<>""),L12,"") | BE12: =IF(AND($I12="yes",$C12>=2000,M12<>""),M12,"") | BF12: =IF(AND($I12="yes",$C12>=2000,N12<>""),N12,"") | BG12: =IF(AND($I12="yes",$C12>=2000,O12<>""),O12,"") | BH12: =IF(AND($I12="yes",$C12>=2000,P12<>""),P12,"") | BI12: =IF(AND($I12="yes",$C12>=2000,Q12<>""),Q12,"") | BJ12: =IF(AND($I12="yes",$C12>=2000,R12<>""),R12,"")
A13: 9 | B13: A RARE, HERMETIC ZINC EXPLORER TRUNK WITH BRASS HARDWARE | C13: 1889 | D13: =IF(C13="","",FLOOR(C13,10)) -> 1880 | E13: Christie's | F13: https://onlineonly.christies.com/s/legendary-trunks-european-private-collection-part-ii/rare-hermetic-zinc-explorer-trunk-brass-hardware-41/262988 | G13: LV0009.png | H13: no | I13: yes | K13: 5 | L13: 5 | M13: 5 | N13: 5 | O13: 1 | P13: 1 | Q13: 5 | R13: 5 | S13: =IF(K13="","",(K13-1)/4) -> 1 | T13: =IF(L13="","",(L13-1)/4) -> 1 | U13: =IF(M13="","",(M13-1)/4) -> 1 | V13: =IF(N13="","",(N13-1)/4) -> 1 | W13: =IF(O13="","",(O13-1)/4) -> 0 | X13: =IF(P13="","",(P13-1)/4) -> 0 | Y13: =IF(Q13="","",(Q13-1)/4) -> 1 | Z13: =IF(R13="","",(R13-1)/4) -> 1 | AA13: =IF(AND(S13<>"",C13<=1949,I13="yes"),S13,"") -> 1 | AB13: =IF(AND(T13<>"",C13<=1949,I13="yes"),T13,"") -> 1 | AC13: =IF(AND(U13<>"",C13<=1949,I13="yes"),U13,"") -> 1 | AD13: =IF(AND(V13<>"",C13<=1949,I13="yes"),V13,"") -> 1 | AE13: =IF(AND(W13<>"",C13<=1949,I13="yes"),W13,"") -> 0 | AF13: =IF(AND(X13<>"",C13<=1949,I13="yes"),X13,"") -> 0 | AG13: =IF(AND(Y13<>"",C13<=1949,I13="yes"),Y13,"") -> 1 | AH13: =IF(AND(Z13<>"",C13<=1949,I13="yes"),Z13,"") -> 1 | AI13: =IF(OR(S13="",'4_BENCHMARK'!$C$4=""),"",ABS(S13-'4_BENCHMARK'!$C$4)) -> 0 | AJ13: =IF(OR(T13="",'4_BENCHMARK'!$C$5=""),"",ABS(T13-'4_BENCHMARK'!$C$5)) -> 0 | AK13: =IF(OR(U13="",'4_BENCHMARK'!$C$6=""),"",ABS(U13-'4_BENCHMARK'!$C$6)) -> 0 | AL13: =IF(OR(V13="",'4_BENCHMARK'!$C$7=""),"",ABS(V13-'4_BENCHMARK'!$C$7)) -> 0 | AM13: =IF(OR(W13="",'4_BENCHMARK'!$C$8=""),"",ABS(W13-'4_BENCHMARK'!$C$8)) -> 0 | AN13: =IF(OR(X13="",'4_BENCHMARK'!$C$9=""),"",ABS(X13-'4_BENCHMARK'!$C$9)) -> 0 | AO13: =IF(OR(Y13="",'4_BENCHMARK'!$C$10=""),"",ABS(Y13-'4_BENCHMARK'!$C$10)) -> 0.5 | AP13: =IF(OR(Z13="",'4_BENCHMARK'!$C$11=""),"",ABS(Z13-'4_BENCHMARK'!$C$11)) -> 0 | AQ13: =IF(COUNT(AI13:AP13)<8,"",1-AVERAGE(AI13:AP13)) -> 0.9375 | AS13: trunk | AT13: =IF(COUNT(AI13:AL13,AO13:AP13)<6,"",1-AVERAGE(AI13:AL13,AO13:AP13)) -> 0.91666667 | AU13: =IF(AND($I13="yes",$C13<=1949,K13<>""),K13,"") -> 5 | AV13: =IF(AND($I13="yes",$C13<=1949,L13<>""),L13,"") -> 5 | AW13: =IF(AND($I13="yes",$C13<=1949,M13<>""),M13,"") -> 5 | AX13: =IF(AND($I13="yes",$C13<=1949,N13<>""),N13,"") -> 5 | AY13: =IF(AND($I13="yes",$C13<=1949,O13<>""),O13,"") -> 1 | AZ13: =IF(AND($I13="yes",$C13<=1949,P13<>""),P13,"") -> 1 | BA13: =IF(AND($I13="yes",$C13<=1949,Q13<>""),Q13,"") -> 5 | BB13: =IF(AND($I13="yes",$C13<=1949,R13<>""),R13,"") -> 5 | BC13: =IF(AND($I13="yes",$C13>=2000,K13<>""),K13,"") | BD13: =IF(AND($I13="yes",$C13>=2000,L13<>""),L13,"") | BE13: =IF(AND($I13="yes",$C13>=2000,M13<>""),M13,"") | BF13: =IF(AND($I13="yes",$C13>=2000,N13<>""),N13,"") | BG13: =IF(AND($I13="yes",$C13>=2000,O13<>""),O13,"") | BH13: =IF(AND($I13="yes",$C13>=2000,P13<>""),P13,"") | BI13: =IF(AND($I13="yes",$C13>=2000,Q13<>""),Q13,"") | BJ13: =IF(AND($I13="yes",$C13>=2000,R13<>""),R13,"")
A14: 10 | B14: A RED VUITTONITE CANVAS TRUNK WITH BRASS HARDWARE | C14: 1926 | D14: =IF(C14="","",FLOOR(C14,10)) -> 1920 | E14: Christie's | F14: https://onlineonly.christies.com/s/legendary-trunks-european-private-collection/red-vuittonite-canvas-trunk-brass-hardware-34/227357 | G14: LV0010.png | H14: no | I14: yes | K14: 5 | L14: 5 | M14: 5 | N14: 5 | O14: 1 | P14: 1 | Q14: 3 | R14: 5 | S14: =IF(K14="","",(K14-1)/4) -> 1 | T14: =IF(L14="","",(L14-1)/4) -> 1 | U14: =IF(M14="","",(M14-1)/4) -> 1 | V14: =IF(N14="","",(N14-1)/4) -> 1 | W14: =IF(O14="","",(O14-1)/4) -> 0 | X14: =IF(P14="","",(P14-1)/4) -> 0 | Y14: =IF(Q14="","",(Q14-1)/4) -> 0.5 | Z14: =IF(R14="","",(R14-1)/4) -> 1 | AA14: =IF(AND(S14<>"",C14<=1949,I14="yes"),S14,"") -> 1 | AB14: =IF(AND(T14<>"",C14<=1949,I14="yes"),T14,"") -> 1 | AC14: =IF(AND(U14<>"",C14<=1949,I14="yes"),U14,"") -> 1 | AD14: =IF(AND(V14<>"",C14<=1949,I14="yes"),V14,"") -> 1 | AE14: =IF(AND(W14<>"",C14<=1949,I14="yes"),W14,"") -> 0 | AF14: =IF(AND(X14<>"",C14<=1949,I14="yes"),X14,"") -> 0 | AG14: =IF(AND(Y14<>"",C14<=1949,I14="yes"),Y14,"") -> 0.5 | AH14: =IF(AND(Z14<>"",C14<=1949,I14="yes"),Z14,"") -> 1 | AI14: =IF(OR(S14="",'4_BENCHMARK'!$C$4=""),"",ABS(S14-'4_BENCHMARK'!$C$4)) -> 0 | AJ14: =IF(OR(T14="",'4_BENCHMARK'!$C$5=""),"",ABS(T14-'4_BENCHMARK'!$C$5)) -> 0 | AK14: =IF(OR(U14="",'4_BENCHMARK'!$C$6=""),"",ABS(U14-'4_BENCHMARK'!$C$6)) -> 0 | AL14: =IF(OR(V14="",'4_BENCHMARK'!$C$7=""),"",ABS(V14-'4_BENCHMARK'!$C$7)) -> 0 | AM14: =IF(OR(W14="",'4_BENCHMARK'!$C$8=""),"",ABS(W14-'4_BENCHMARK'!$C$8)) -> 0 | AN14: =IF(OR(X14="",'4_BENCHMARK'!$C$9=""),"",ABS(X14-'4_BENCHMARK'!$C$9)) -> 0 | AO14: =IF(OR(Y14="",'4_BENCHMARK'!$C$10=""),"",ABS(Y14-'4_BENCHMARK'!$C$10)) -> 0 | AP14: =IF(OR(Z14="",'4_BENCHMARK'!$C$11=""),"",ABS(Z14-'4_BENCHMARK'!$C$11)) -> 0 | AQ14: =IF(COUNT(AI14:AP14)<8,"",1-AVERAGE(AI14:AP14)) -> 1 | AS14: trunk | AT14: =IF(COUNT(AI14:AL14,AO14:AP14)<6,"",1-AVERAGE(AI14:AL14,AO14:AP14)) -> 1 | AU14: =IF(AND($I14="yes",$C14<=1949,K14<>""),K14,"") -> 5 | AV14: =IF(AND($I14="yes",$C14<=1949,L14<>""),L14,"") -> 5 | AW14: =IF(AND($I14="yes",$C14<=1949,M14<>""),M14,"") -> 5 | AX14: =IF(AND($I14="yes",$C14<=1949,N14<>""),N14,"") -> 5 | AY14: =IF(AND($I14="yes",$C14<=1949,O14<>""),O14,"") -> 1 | AZ14: =IF(AND($I14="yes",$C14<=1949,P14<>""),P14,"") -> 1 | BA14: =IF(AND($I14="yes",$C14<=1949,Q14<>""),Q14,"") -> 3 | BB14: =IF(AND($I14="yes",$C14<=1949,R14<>""),R14,"") -> 5 | BC14: =IF(AND($I14="yes",$C14>=2000,K14<>""),K14,"") | BD14: =IF(AND($I14="yes",$C14>=2000,L14<>""),L14,"") | BE14: =IF(AND($I14="yes",$C14>=2000,M14<>""),M14,"") | BF14: =IF(AND($I14="yes",$C14>=2000,N14<>""),N14,"") | BG14: =IF(AND($I14="yes",$C14>=2000,O14<>""),O14,"") | BH14: =IF(AND($I14="yes",$C14>=2000,P14<>""),P14,"") | BI14: =IF(AND($I14="yes",$C14>=2000,Q14<>""),Q14,"") | BJ14: =IF(AND($I14="yes",$C14>=2000,R14<>""),R14,"")
A15: 11 | B15: A MONOGRAM CANVAS DESK TRUNK FOR THIRTY PAIRS OF SHOES WITH BRASS HARDWARE | C15: 1929 | D15: =IF(C15="","",FLOOR(C15,10)) -> 1920 | E15: Christie's | F15: https://onlineonly.christies.com/s/legendary-trunks-european-private-collection-part-ii/monogram-canvas-desk-trunk-thirty-pairs-shoes-brass-hardware-31/262977 | G15: LV0011.png | H15: no | I15: yes | K15: 5 | L15: 5 | M15: 5 | N15: 5 | O15: 5 | P15: 5 | Q15: 2 | R15: 5 | S15: =IF(K15="","",(K15-1)/4) -> 1 | T15: =IF(L15="","",(L15-1)/4) -> 1 | U15: =IF(M15="","",(M15-1)/4) -> 1 | V15: =IF(N15="","",(N15-1)/4) -> 1 | W15: =IF(O15="","",(O15-1)/4) -> 1 | X15: =IF(P15="","",(P15-1)/4) -> 1 | Y15: =IF(Q15="","",(Q15-1)/4) -> 0.25 | Z15: =IF(R15="","",(R15-1)/4) -> 1 | AA15: =IF(AND(S15<>"",C15<=1949,I15="yes"),S15,"") -> 1 | AB15: =IF(AND(T15<>"",C15<=1949,I15="yes"),T15,"") -> 1 | AC15: =IF(AND(U15<>"",C15<=1949,I15="yes"),U15,"") -> 1 | AD15: =IF(AND(V15<>"",C15<=1949,I15="yes"),V15,"") -> 1 | AE15: =IF(AND(W15<>"",C15<=1949,I15="yes"),W15,"") -> 1 | AF15: =IF(AND(X15<>"",C15<=1949,I15="yes"),X15,"") -> 1 | AG15: =IF(AND(Y15<>"",C15<=1949,I15="yes"),Y15,"") -> 0.25 | AH15: =IF(AND(Z15<>"",C15<=1949,I15="yes"),Z15,"") -> 1 | AI15: =IF(OR(S15="",'4_BENCHMARK'!$C$4=""),"",ABS(S15-'4_BENCHMARK'!$C$4)) -> 0 | AJ15: =IF(OR(T15="",'4_BENCHMARK'!$C$5=""),"",ABS(T15-'4_BENCHMARK'!$C$5)) -> 0 | AK15: =IF(OR(U15="",'4_BENCHMARK'!$C$6=""),"",ABS(U15-'4_BENCHMARK'!$C$6)) -> 0 | AL15: =IF(OR(V15="",'4_BENCHMARK'!$C$7=""),"",ABS(V15-'4_BENCHMARK'!$C$7)) -> 0 | AM15: =IF(OR(W15="",'4_BENCHMARK'!$C$8=""),"",ABS(W15-'4_BENCHMARK'!$C$8)) -> 1 | AN15: =IF(OR(X15="",'4_BENCHMARK'!$C$9=""),"",ABS(X15-'4_BENCHMARK'!$C$9)) -> 1 | AO15: =IF(OR(Y15="",'4_BENCHMARK'!$C$10=""),"",ABS(Y15-'4_BENCHMARK'!$C$10)) -> 0.25 | AP15: =IF(OR(Z15="",'4_BENCHMARK'!$C$11=""),"",ABS(Z15-'4_BENCHMARK'!$C$11)) -> 0 | AQ15: =IF(COUNT(AI15:AP15)<8,"",1-AVERAGE(AI15:AP15)) -> 0.71875 | AS15: trunk | AT15: =IF(COUNT(AI15:AL15,AO15:AP15)<6,"",1-AVERAGE(AI15:AL15,AO15:AP15)) -> 0.95833333 | AU15: =IF(AND($I15="yes",$C15<=1949,K15<>""),K15,"") -> 5 | AV15: =IF(AND($I15="yes",$C15<=1949,L15<>""),L15,"") -> 5 | AW15: =IF(AND($I15="yes",$C15<=1949,M15<>""),M15,"") -> 5 | AX15: =IF(AND($I15="yes",$C15<=1949,N15<>""),N15,"") -> 5 | AY15: =IF(AND($I15="yes",$C15<=1949,O15<>""),O15,"") -> 5 | AZ15: =IF(AND($I15="yes",$C15<=1949,P15<>""),P15,"") -> 5 | BA15: =IF(AND($I15="yes",$C15<=1949,Q15<>""),Q15,"") -> 2 | BB15: =IF(AND($I15="yes",$C15<=1949,R15<>""),R15,"") -> 5 | BC15: =IF(AND($I15="yes",$C15>=2000,K15<>""),K15,"") | BD15: =IF(AND($I15="yes",$C15>=2000,L15<>""),L15,"") | BE15: =IF(AND($I15="yes",$C15>=2000,M15<>""),M15,"") | BF15: =IF(AND($I15="yes",$C15>=2000,N15<>""),N15,"") | BG15: =IF(AND($I15="yes",$C15>=2000,O15<>""),O15,"") | BH15: =IF(AND($I15="yes",$C15>=2000,P15<>""),P15,"") | BI15: =IF(AND($I15="yes",$C15>=2000,Q15<>""),Q15,"") | BJ15: =IF(AND($I15="yes",$C15>=2000,R15<>""),R15,"")
A16: 12 | B16: A MONOGRAM CANVAS LIBRARY TRUNK WITH BRASS HARDWARE | C16: 1932 | D16: =IF(C16="","",FLOOR(C16,10)) -> 1930 | E16: Christie's | F16: https://onlineonly.christies.com/s/legendary-trunks-european-private-collection/monogram-canvas-library-trunk-brass-hardware-22/227559 | G16: LV0012.png | H16: no | I16: yes | K16: 5 | L16: 5 | M16: 5 | N16: 5 | O16: 5 | P16: 5 | Q16: 2 | R16: 5 | S16: =IF(K16="","",(K16-1)/4) -> 1 | T16: =IF(L16="","",(L16-1)/4) -> 1 | U16: =IF(M16="","",(M16-1)/4) -> 1 | V16: =IF(N16="","",(N16-1)/4) -> 1 | W16: =IF(O16="","",(O16-1)/4) -> 1 | X16: =IF(P16="","",(P16-1)/4) -> 1 | Y16: =IF(Q16="","",(Q16-1)/4) -> 0.25 | Z16: =IF(R16="","",(R16-1)/4) -> 1 | AA16: =IF(AND(S16<>"",C16<=1949,I16="yes"),S16,"") -> 1 | AB16: =IF(AND(T16<>"",C16<=1949,I16="yes"),T16,"") -> 1 | AC16: =IF(AND(U16<>"",C16<=1949,I16="yes"),U16,"") -> 1 | AD16: =IF(AND(V16<>"",C16<=1949,I16="yes"),V16,"") -> 1 | AE16: =IF(AND(W16<>"",C16<=1949,I16="yes"),W16,"") -> 1 | AF16: =IF(AND(X16<>"",C16<=1949,I16="yes"),X16,"") -> 1 | AG16: =IF(AND(Y16<>"",C16<=1949,I16="yes"),Y16,"") -> 0.25 | AH16: =IF(AND(Z16<>"",C16<=1949,I16="yes"),Z16,"") -> 1 | AI16: =IF(OR(S16="",'4_BENCHMARK'!$C$4=""),"",ABS(S16-'4_BENCHMARK'!$C$4)) -> 0 | AJ16: =IF(OR(T16="",'4_BENCHMARK'!$C$5=""),"",ABS(T16-'4_BENCHMARK'!$C$5)) -> 0 | AK16: =IF(OR(U16="",'4_BENCHMARK'!$C$6=""),"",ABS(U16-'4_BENCHMARK'!$C$6)) -> 0 | AL16: =IF(OR(V16="",'4_BENCHMARK'!$C$7=""),"",ABS(V16-'4_BENCHMARK'!$C$7)) -> 0 | AM16: =IF(OR(W16="",'4_BENCHMARK'!$C$8=""),"",ABS(W16-'4_BENCHMARK'!$C$8)) -> 1 | AN16: =IF(OR(X16="",'4_BENCHMARK'!$C$9=""),"",ABS(X16-'4_BENCHMARK'!$C$9)) -> 1 | AO16: =IF(OR(Y16="",'4_BENCHMARK'!$C$10=""),"",ABS(Y16-'4_BENCHMARK'!$C$10)) -> 0.25 | AP16: =IF(OR(Z16="",'4_BENCHMARK'!$C$11=""),"",ABS(Z16-'4_BENCHMARK'!$C$11)) -> 0 | AQ16: =IF(COUNT(AI16:AP16)<8,"",1-AVERAGE(AI16:AP16)) -> 0.71875 | AS16: trunk | AT16: =IF(COUNT(AI16:AL16,AO16:AP16)<6,"",1-AVERAGE(AI16:AL16,AO16:AP16)) -> 0.95833333 | AU16: =IF(AND($I16="yes",$C16<=1949,K16<>""),K16,"") -> 5 | AV16: =IF(AND($I16="yes",$C16<=1949,L16<>""),L16,"") -> 5 | AW16: =IF(AND($I16="yes",$C16<=1949,M16<>""),M16,"") -> 5 | AX16: =IF(AND($I16="yes",$C16<=1949,N16<>""),N16,"") -> 5 | AY16: =IF(AND($I16="yes",$C16<=1949,O16<>""),O16,"") -> 5 | AZ16: =IF(AND($I16="yes",$C16<=1949,P16<>""),P16,"") -> 5 | BA16: =IF(AND($I16="yes",$C16<=1949,Q16<>""),Q16,"") -> 2 | BB16: =IF(AND($I16="yes",$C16<=1949,R16<>""),R16,"") -> 5 | BC16: =IF(AND($I16="yes",$C16>=2000,K16<>""),K16,"") | BD16: =IF(AND($I16="yes",$C16>=2000,L16<>""),L16,"") | BE16: =IF(AND($I16="yes",$C16>=2000,M16<>""),M16,"") | BF16: =IF(AND($I16="yes",$C16>=2000,N16<>""),N16,"") | BG16: =IF(AND($I16="yes",$C16>=2000,O16<>""),O16,"") | BH16: =IF(AND($I16="yes",$C16>=2000,P16<>""),P16,"") | BI16: =IF(AND($I16="yes",$C16>=2000,Q16<>""),Q16,"") | BJ16: =IF(AND($I16="yes",$C16>=2000,R16<>""),R16,"")
... A40: 36 | B40: AN ORANGE VUITTONITE CANVAS DOUBLE-DRAWER WARDROBE TRUNK WITH BRASS HARDWARE | C40: 1951 | D40: =IF(C40="","",FLOOR(C40,10)) -> 1950 | E40: Christie's | F40: https://onlineonly.christies.com/s/legendary-trunks-european-private-collection/orange-vuittonite-canvas-double-drawer-wardrobe-trunk-brass-hardware-30/227355 | G40: LV0036.png | H40: no | I40: yes | K40: 5 | L40: 5 | M40: 5 | N40: 5 | O40: 1 | P40: 1 | Q40: 2 | R40: 5 | S40: =IF(K40="","",(K40-1)/4) -> 1 | T40: =IF(L40="","",(L40-1)/4) -> 1 | U40: =IF(M40="","",(M40-1)/4) -> 1 | V40: =IF(N40="","",(N40-1)/4) -> 1 | W40: =IF(O40="","",(O40-1)/4) -> 0 | X40: =IF(P40="","",(P40-1)/4) -> 0 | Y40: =IF(Q40="","",(Q40-1)/4) -> 0.25 | Z40: =IF(R40="","",(R40-1)/4) -> 1 | AA40: =IF(AND(S40<>"",C40<=1949,I40="yes"),S40,"") | AB40: =IF(AND(T40<>"",C40<=1949,I40="yes"),T40,"") | AC40: =IF(AND(U40<>"",C40<=1949,I40="yes"),U40,"") | AD40: =IF(AND(V40<>"",C40<=1949,I40="yes"),V40,"") | AE40: =IF(AND(W40<>"",C40<=1949,I40="yes"),W40,"") | AF40: =IF(AND(X40<>"",C40<=1949,I40="yes"),X40,"") | AG40: =IF(AND(Y40<>"",C40<=1949,I40="yes"),Y40,"") | AH40: =IF(AND(Z40<>"",C40<=1949,I40="yes"),Z40,"") | AI40: =IF(OR(S40="",'4_BENCHMARK'!$C$4=""),"",ABS(S40-'4_BENCHMARK'!$C$4)) -> 0 | AJ40: =IF(OR(T40="",'4_BENCHMARK'!$C$5=""),"",ABS(T40-'4_BENCHMARK'!$C$5)) -> 0 | AK40: =IF(OR(U40="",'4_BENCHMARK'!$C$6=""),"",ABS(U40-'4_BENCHMARK'!$C$6)) -> 0 | AL40: =IF(OR(V40="",'4_BENCHMARK'!$C$7=""),"",ABS(V40-'4_BENCHMARK'!$C$7)) -> 0 | AM40: =IF(OR(W40="",'4_BENCHMARK'!$C$8=""),"",ABS(W40-'4_BENCHMARK'!$C$8)) -> 0 | AN40: =IF(OR(X40="",'4_BENCHMARK'!$C$9=""),"",ABS(X40-'4_BENCHMARK'!$C$9)) -> 0 | AO40: =IF(OR(Y40="",'4_BENCHMARK'!$C$10=""),"",ABS(Y40-'4_BENCHMARK'!$C$10)) -> 0.25 | AP40: =IF(OR(Z40="",'4_BENCHMARK'!$C$11=""),"",ABS(Z40-'4_BENCHMARK'!$C$11)) -> 0 | AQ40: =IF(COUNT(AI40:AP40)<8,"",1-AVERAGE(AI40:AP40)) -> 0.96875 | AS40: trunk | AT40: =IF(COUNT(AI40:AL40,AO40:AP40)<6,"",1-AVERAGE(AI40:AL40,AO40:AP40)) -> 0.95833333 | AU40: =IF(AND($I40="yes",$C40<=1949,K40<>""),K40,"") | AV40: =IF(AND($I40="yes",$C40<=1949,L40<>""),L40,"") | AW40: =IF(AND($I40="yes",$C40<=1949,M40<>""),M40,"") | AX40: =IF(AND($I40="yes",$C40<=1949,N40<>""),N40,"") | AY40: =IF(AND($I40="yes",$C40<=1949,O40<>""),O40,"") | AZ40: =IF(AND($I40="yes",$C40<=1949,P40<>""),P40,"") | BA40: =IF(AND($I40="yes",$C40<=1949,Q40<>""),Q40,"") | BB40: =IF(AND($I40="yes",$C40<=1949,R40<>""),R40,"") | BC40: =IF(AND($I40="yes",$C40>=2000,K40<>""),K40,"") | BD40: =IF(AND($I40="yes",$C40>=2000,L40<>""),L40,"") | BE40: =IF(AND($I40="yes",$C40>=2000,M40<>""),M40,"") | BF40: =IF(AND($I40="yes",$C40>=2000,N40<>""),N40,"") | BG40: =IF(AND($I40="yes",$C40>=2000,O40<>""),O40,"") | BH40: =IF(AND($I40="yes",$C40>=2000,P40<>""),P40,"") | BI40: =IF(AND($I40="yes",$C40>=2000,Q40<>""),Q40,"") | BJ40: =IF(AND($I40="yes",$C40>=2000,R40<>""),R40,"")
A41: 37 | B41: A MAHOGANY RUNNING-BOARD TRUNK FOR AUTOMOBILE TOOLS WITH BRASS HARDWARE | C41: 1910 | D41: =IF(C41="","",FLOOR(C41,10)) -> 1910 | E41: Christie's | F41: https://onlineonly.christies.com/s/legendary-trunks-european-private-collection/mahogany-running-board-trunk-automobile-tools-brass-hardware-83/227592 | G41: LV0037.png | H41: no | I41: yes | J41: circa 1910 | K41: 5 | L41: 4 | M41: 5 | N41: 5 | O41: 1 | P41: 1 | Q41: 2 | R41: 5 | S41: =IF(K41="","",(K41-1)/4) -> 1 | T41: =IF(L41="","",(L41-1)/4) -> 0.75 | U41: =IF(M41="","",(M41-1)/4) -> 1 | V41: =IF(N41="","",(N41-1)/4) -> 1 | W41: =IF(O41="","",(O41-1)/4) -> 0 | X41: =IF(P41="","",(P41-1)/4) -> 0 | Y41: =IF(Q41="","",(Q41-1)/4) -> 0.25 | Z41: =IF(R41="","",(R41-1)/4) -> 1 | AA41: =IF(AND(S41<>"",C41<=1949,I41="yes"),S41,"") -> 1 | AB41: =IF(AND(T41<>"",C41<=1949,I41="yes"),T41,"") -> 0.75 | AC41: =IF(AND(U41<>"",C41<=1949,I41="yes"),U41,"") -> 1 | AD41: =IF(AND(V41<>"",C41<=1949,I41="yes"),V41,"") -> 1 | AE41: =IF(AND(W41<>"",C41<=1949,I41="yes"),W41,"") -> 0 | AF41: =IF(AND(X41<>"",C41<=1949,I41="yes"),X41,"") -> 0 | AG41: =IF(AND(Y41<>"",C41<=1949,I41="yes"),Y41,"") -> 0.25 | AH41: =IF(AND(Z41<>"",C41<=1949,I41="yes"),Z41,"") -> 1 | AI41: =IF(OR(S41="",'4_BENCHMARK'!$C$4=""),"",ABS(S41-'4_BENCHMARK'!$C$4)) -> 0 | AJ41: =IF(OR(T41="",'4_BENCHMARK'!$C$5=""),"",ABS(T41-'4_BENCHMARK'!$C$5)) -> 0.25 | AK41: =IF(OR(U41="",'4_BENCHMARK'!$C$6=""),"",ABS(U41-'4_BENCHMARK'!$C$6)) -> 0 | AL41: =IF(OR(V41="",'4_BENCHMARK'!$C$7=""),"",ABS(V41-'4_BENCHMARK'!$C$7)) -> 0 | AM41: =IF(OR(W41="",'4_BENCHMARK'!$C$8=""),"",ABS(W41-'4_BENCHMARK'!$C$8)) -> 0 | AN41: =IF(OR(X41="",'4_BENCHMARK'!$C$9=""),"",ABS(X41-'4_BENCHMARK'!$C$9)) -> 0 | AO41: =IF(OR(Y41="",'4_BENCHMARK'!$C$10=""),"",ABS(Y41-'4_BENCHMARK'!$C$10)) -> 0.25 | AP41: =IF(OR(Z41="",'4_BENCHMARK'!$C$11=""),"",ABS(Z41-'4_BENCHMARK'!$C$11)) -> 0 | AQ41: =IF(COUNT(AI41:AP41)<8,"",1-AVERAGE(AI41:AP41)) -> 0.9375 | AR41: yes | AS41: trunk | AT41: =IF(COUNT(AI41:AL41,AO41:AP41)<6,"",1-AVERAGE(AI41:AL41,AO41:AP41)) -> 0.91666667 | AU41: =IF(AND($I41="yes",$C41<=1949,K41<>""),K41,"") -> 5 | AV41: =IF(AND($I41="yes",$C41<=1949,L41<>""),L41,"") -> 4 | AW41: =IF(AND($I41="yes",$C41<=1949,M41<>""),M41,"") -> 5 | AX41: =IF(AND($I41="yes",$C41<=1949,N41<>""),N41,"") -> 5 | AY41: =IF(AND($I41="yes",$C41<=1949,O41<>""),O41,"") -> 1 | AZ41: =IF(AND($I41="yes",$C41<=1949,P41<>""),P41,"") -> 1 | BA41: =IF(AND($I41="yes",$C41<=1949,Q41<>""),Q41,"") -> 2 | BB41: =IF(AND($I41="yes",$C41<=1949,R41<>""),R41,"") -> 5 | BC41: =IF(AND($I41="yes",$C41>=2000,K41<>""),K41,"") | BD41: =IF(AND($I41="yes",$C41>=2000,L41<>""),L41,"") | BE41: =IF(AND($I41="yes",$C41>=2000,M41<>""),M41,"") | BF41: =IF(AND($I41="yes",$C41>=2000,N41<>""),N41,"") | BG41: =IF(AND($I41="yes",$C41>=2000,O41<>""),O41,"") | BH41: =IF(AND($I41="yes",$C41>=2000,P41<>""),P41,"") | BI41: =IF(AND($I41="yes",$C41>=2000,Q41<>""),Q41,"") | BJ41: =IF(AND($I41="yes",$C41>=2000,R41<>""),R41,"")
A42: 38 | B42: A VERY RARE, BROWN AND TAN PATTERNED STENCILED CANVAS & WOOD MALLE COURRIER 110 | C42: 1890 | D42: =IF(C42="","",FLOOR(C42,10)) -> 1890 | E42: Christie's | F42: https://onlineonly.christies.com/s/handbags-online-new-york-edit/very-rare-brown-tan-patterned-stenciled-canvas-wood-malle-courrier-110-63/205210 | G42: LV0038.png | H42: no | I42: yes | J42: circa 1890 | K42: 5 | L42: 5 | M42: 5 | N42: 5 | O42: 1 | P42: 1 | Q42: 2 | R42: 5 | S42: =IF(K42="","",(K42-1)/4) -> 1 | T42: =IF(L42="","",(L42-1)/4) -> 1 | U42: =IF(M42="","",(M42-1)/4) -> 1 | V42: =IF(N42="","",(N42-1)/4) -> 1 | W42: =IF(O42="","",(O42-1)/4) -> 0 | X42: =IF(P42="","",(P42-1)/4) -> 0 | Y42: =IF(Q42="","",(Q42-1)/4) -> 0.25 | Z42: =IF(R42="","",(R42-1)/4) -> 1 | AA42: =IF(AND(S42<>"",C42<=1949,I42="yes"),S42,"") -> 1 | AB42: =IF(AND(T42<>"",C42<=1949,I42="yes"),T42,"") -> 1 | AC42: =IF(AND(U42<>"",C42<=1949,I42="yes"),U42,"") -> 1 | AD42: =IF(AND(V42<>"",C42<=1949,I42="yes"),V42,"") -> 1 | AE42: =IF(AND(W42<>"",C42<=1949,I42="yes"),W42,"") -> 0 | AF42: =IF(AND(X42<>"",C42<=1949,I42="yes"),X42,"") -> 0 | AG42: =IF(AND(Y42<>"",C42<=1949,I42="yes"),Y42,"") -> 0.25 | AH42: =IF(AND(Z42<>"",C42<=1949,I42="yes"),Z42,"") -> 1 | AI42: =IF(OR(S42="",'4_BENCHMARK'!$C$4=""),"",ABS(S42-'4_BENCHMARK'!$C$4)) -> 0 | AJ42: =IF(OR(T42="",'4_BENCHMARK'!$C$5=""),"",ABS(T42-'4_BENCHMARK'!$C$5)) -> 0 | AK42: =IF(OR(U42="",'4_BENCHMARK'!$C$6=""),"",ABS(U42-'4_BENCHMARK'!$C$6)) -> 0 | AL42: =IF(OR(V42="",'4_BENCHMARK'!$C$7=""),"",ABS(V42-'4_BENCHMARK'!$C$7)) -> 0 | AM42: =IF(OR(W42="",'4_BENCHMARK'!$C$8=""),"",ABS(W42-'4_BENCHMARK'!$C$8)) -> 0 | AN42: =IF(OR(X42="",'4_BENCHMARK'!$C$9=""),"",ABS(X42-'4_BENCHMARK'!$C$9)) -> 0 | AO42: =IF(OR(Y42="",'4_BENCHMARK'!$C$10=""),"",ABS(Y42-'4_BENCHMARK'!$C$10)) -> 0.25 | AP42: =IF(OR(Z42="",'4_BENCHMARK'!$C$11=""),"",ABS(Z42-'4_BENCHMARK'!$C$11)) -> 0 | AQ42: =IF(COUNT(AI42:AP42)<8,"",1-AVERAGE(AI42:AP42)) -> 0.96875 | AS42: trunk | AT42: =IF(COUNT(AI42:AL42,AO42:AP42)<6,"",1-AVERAGE(AI42:AL42,AO42:AP42)) -> 0.95833333 | AU42: =IF(AND($I42="yes",$C42<=1949,K42<>""),K42,"") -> 5 | AV42: =IF(AND($I42="yes",$C42<=1949,L42<>""),L42,"") -> 5 | AW42: =IF(AND($I42="yes",$C42<=1949,M42<>""),M42,"") -> 5 | AX42: =IF(AND($I42="yes",$C42<=1949,N42<>""),N42,"") -> 5 | AY42: =IF(AND($I42="yes",$C42<=1949,O42<>""),O42,"") -> 1 | AZ42: =IF(AND($I42="yes",$C42<=1949,P42<>""),P42,"") -> 1 | BA42: =IF(AND($I42="yes",$C42<=1949,Q42<>""),Q42,"") -> 2 | BB42: =IF(AND($I42="yes",$C42<=1949,R42<>""),R42,"") -> 5 | BC42: =IF(AND($I42="yes",$C42>=2000,K42<>""),K42,"") | BD42: =IF(AND($I42="yes",$C42>=2000,L42<>""),L42,"") | BE42: =IF(AND($I42="yes",$C42>=2000,M42<>""),M42,"") | BF42: =IF(AND($I42="yes",$C42>=2000,N42<>""),N42,"") | BG42: =IF(AND($I42="yes",$C42>=2000,O42<>""),O42,"") | BH42: =IF(AND($I42="yes",$C42>=2000,P42<>""),P42,"") | BI42: =IF(AND($I42="yes",$C42>=2000,Q42<>""),Q42,"") | BJ42: =IF(AND($I42="yes",$C42>=2000,R42<>""),R42,"")
A43: 39 | B43: A CUSTOM GRAPHITE DAMIER CANVAS WATCH & JEWELLERY TRUNK | C43: 2016 | D43: =IF(C43="","",FLOOR(C43,10)) -> 2010 | E43: Christie's | F43: https://www.christies.com/en/lot/lot-6144072 | G43: LV0039.png | H43: yes | I43: yes | K43: 5 | L43: 5 | M43: 5 | N43: 5 | O43: 1 | P43: 1 | Q43: 2 | R43: 5 | S43: =IF(K43="","",(K43-1)/4) -> 1 | T43: =IF(L43="","",(L43-1)/4) -> 1 | U43: =IF(M43="","",(M43-1)/4) -> 1 | V43: =IF(N43="","",(N43-1)/4) -> 1 | W43: =IF(O43="","",(O43-1)/4) -> 0 | X43: =IF(P43="","",(P43-1)/4) -> 0 | Y43: =IF(Q43="","",(Q43-1)/4) -> 0.25 | Z43: =IF(R43="","",(R43-1)/4) -> 1 | AA43: =IF(AND(S43<>"",C43<=1949,I43="yes"),S43,"") | AB43: =IF(AND(T43<>"",C43<=1949,I43="yes"),T43,"") | AC43: =IF(AND(U43<>"",C43<=1949,I43="yes"),U43,"") | AD43: =IF(AND(V43<>"",C43<=1949,I43="yes"),V43,"") | AE43: =IF(AND(W43<>"",C43<=1949,I43="yes"),W43,"") | AF43: =IF(AND(X43<>"",C43<=1949,I43="yes"),X43,"") | AG43: =IF(AND(Y43<>"",C43<=1949,I43="yes"),Y43,"") | AH43: =IF(AND(Z43<>"",C43<=1949,I43="yes"),Z43,"") | AI43: =IF(OR(S43="",'4_BENCHMARK'!$C$4=""),"",ABS(S43-'4_BENCHMARK'!$C$4)) -> 0 | AJ43: =IF(OR(T43="",'4_BENCHMARK'!$C$5=""),"",ABS(T43-'4_BENCHMARK'!$C$5)) -> 0 | AK43: =IF(OR(U43="",'4_BENCHMARK'!$C$6=""),"",ABS(U43-'4_BENCHMARK'!$C$6)) -> 0 | AL43: =IF(OR(V43="",'4_BENCHMARK'!$C$7=""),"",ABS(V43-'4_BENCHMARK'!$C$7)) -> 0 | AM43: =IF(OR(W43="",'4_BENCHMARK'!$C$8=""),"",ABS(W43-'4_BENCHMARK'!$C$8)) -> 0 | AN43: =IF(OR(X43="",'4_BENCHMARK'!$C$9=""),"",ABS(X43-'4_BENCHMARK'!$C$9)) -> 0 | AO43: =IF(OR(Y43="",'4_BENCHMARK'!$C$10=""),"",ABS(Y43-'4_BENCHMARK'!$C$10)) -> 0.25 | AP43: =IF(OR(Z43="",'4_BENCHMARK'!$C$11=""),"",ABS(Z43-'4_BENCHMARK'!$C$11)) -> 0 | AQ43: =IF(COUNT(AI43:AP43)<8,"",1-AVERAGE(AI43:AP43)) -> 0.96875 | AS43: trunk | AT43: =IF(COUNT(AI43:AL43,AO43:AP43)<6,"",1-AVERAGE(AI43:AL43,AO43:AP43)) -> 0.95833333 | AU43: =IF(AND($I43="yes",$C43<=1949,K43<>""),K43,"") | AV43: =IF(AND($I43="yes",$C43<=1949,L43<>""),L43,"") | AW43: =IF(AND($I43="yes",$C43<=1949,M43<>""),M43,"") | AX43: =IF(AND($I43="yes",$C43<=1949,N43<>""),N43,"") | AY43: =IF(AND($I43="yes",$C43<=1949,O43<>""),O43,"") | AZ43: =IF(AND($I43="yes",$C43<=1949,P43<>""),P43,"") | BA43: =IF(AND($I43="yes",$C43<=1949,Q43<>""),Q43,"") | BB43: =IF(AND($I43="yes",$C43<=1949,R43<>""),R43,"") | BC43: =IF(AND($I43="yes",$C43>=2000,K43<>""),K43,"") -> 5 | BD43: =IF(AND($I43="yes",$C43>=2000,L43<>""),L43,"") -> 5 | BE43: =IF(AND($I43="yes",$C43>=2000,M43<>""),M43,"") -> 5 | BF43: =IF(AND($I43="yes",$C43>=2000,N43<>""),N43,"") -> 5 | BG43: =IF(AND($I43="yes",$C43>=2000,O43<>""),O43,"") -> 1 | BH43: =IF(AND($I43="yes",$C43>=2000,P43<>""),P43,"") -> 1 | BI43: =IF(AND($I43="yes",$C43>=2000,Q43<>""),Q43,"") -> 2 | BJ43: =IF(AND($I43="yes",$C43>=2000,R43<>""),R43,"") -> 5
A44: 40 | B44: A NATURAL COWHIDE LEATHER IDEAL TRUNK WITH BRASS HARDWARE | C44: 1894 | D44: =IF(C44="","",FLOOR(C44,10)) -> 1890 | E44: Christie's | F44: https://onlineonly.christies.com/s/legendary-trunks-european-private-collection/natural-cowhide-leather-ideal-trunk-brass-hardware-5/227546 | G44: LV0040.png | H44: no | I44: yes | K44: 4 | L44: 5 | M44: 5 | N44: 5 | O44: 1 | P44: 1 | Q44: 2 | R44: 5 | S44: =IF(K44="","",(K44-1)/4) -> 0.75 | T44: =IF(L44="","",(L44-1)/4) -> 1 | U44: =IF(M44="","",(M44-1)/4) -> 1 | V44: =IF(N44="","",(N44-1)/4) -> 1 | W44: =IF(O44="","",(O44-1)/4) -> 0 | X44: =IF(P44="","",(P44-1)/4) -> 0 | Y44: =IF(Q44="","",(Q44-1)/4) -> 0.25 | Z44: =IF(R44="","",(R44-1)/4) -> 1 | AA44: =IF(AND(S44<>"",C44<=1949,I44="yes"),S44,"") -> 0.75 | AB44: =IF(AND(T44<>"",C44<=1949,I44="yes"),T44,"") -> 1 | AC44: =IF(AND(U44<>"",C44<=1949,I44="yes"),U44,"") -> 1 | AD44: =IF(AND(V44<>"",C44<=1949,I44="yes"),V44,"") -> 1 | AE44: =IF(AND(W44<>"",C44<=1949,I44="yes"),W44,"") -> 0 | AF44: =IF(AND(X44<>"",C44<=1949,I44="yes"),X44,"") -> 0 | AG44: =IF(AND(Y44<>"",C44<=1949,I44="yes"),Y44,"") -> 0.25 | AH44: =IF(AND(Z44<>"",C44<=1949,I44="yes"),Z44,"") -> 1 | AI44: =IF(OR(S44="",'4_BENCHMARK'!$C$4=""),"",ABS(S44-'4_BENCHMARK'!$C$4)) -> 0.25 | AJ44: =IF(OR(T44="",'4_BENCHMARK'!$C$5=""),"",ABS(T44-'4_BENCHMARK'!$C$5)) -> 0 | AK44: =IF(OR(U44="",'4_BENCHMARK'!$C$6=""),"",ABS(U44-'4_BENCHMARK'!$C$6)) -> 0 | AL44: =IF(OR(V44="",'4_BENCHMARK'!$C$7=""),"",ABS(V44-'4_BENCHMARK'!$C$7)) -> 0 | AM44: =IF(OR(W44="",'4_BENCHMARK'!$C$8=""),"",ABS(W44-'4_BENCHMARK'!$C$8)) -> 0 | AN44: =IF(OR(X44="",'4_BENCHMARK'!$C$9=""),"",ABS(X44-'4_BENCHMARK'!$C$9)) -> 0 | AO44: =IF(OR(Y44="",'4_BENCHMARK'!$C$10=""),"",ABS(Y44-'4_BENCHMARK'!$C$10)) -> 0.25 | AP44: =IF(OR(Z44="",'4_BENCHMARK'!$C$11=""),"",ABS(Z44-'4_BENCHMARK'!$C$11)) -> 0 | AQ44: =IF(COUNT(AI44:AP44)<8,"",1-AVERAGE(AI44:AP44)) -> 0.9375 | AS44: trunk | AT44: =IF(COUNT(AI44:AL44,AO44:AP44)<6,"",1-AVERAGE(AI44:AL44,AO44:AP44)) -> 0.91666667 | AU44: =IF(AND($I44="yes",$C44<=1949,K44<>""),K44,"") -> 4 | AV44: =IF(AND($I44="yes",$C44<=1949,L44<>""),L44,"") -> 5 | AW44: =IF(AND($I44="yes",$C44<=1949,M44<>""),M44,"") -> 5 | AX44: =IF(AND($I44="yes",$C44<=1949,N44<>""),N44,"") -> 5 | AY44: =IF(AND($I44="yes",$C44<=1949,O44<>""),O44,"") -> 1 | AZ44: =IF(AND($I44="yes",$C44<=1949,P44<>""),P44,"") -> 1 | BA44: =IF(AND($I44="yes",$C44<=1949,Q44<>""),Q44,"") -> 2 | BB44: =IF(AND($I44="yes",$C44<=1949,R44<>""),R44,"") -> 5 | BC44: =IF(AND($I44="yes",$C44>=2000,K44<>""),K44,"") | BD44: =IF(AND($I44="yes",$C44>=2000,L44<>""),L44,"") | BE44: =IF(AND($I44="yes",$C44>=2000,M44<>""),M44,"") | BF44: =IF(AND($I44="yes",$C44>=2000,N44<>""),N44,"") | BG44: =IF(AND($I44="yes",$C44>=2000,O44<>""),O44,"") | BH44: =IF(AND($I44="yes",$C44>=2000,P44<>""),P44,"") | BI44: =IF(AND($I44="yes",$C44>=2000,Q44<>""),Q44,"") | BJ44: =IF(AND($I44="yes",$C44>=2000,R44<>""),R44,"")
A45: 41 | B45: A LIMITED EDITION CLASSIC MONOGRAM CANVAS & BLACK CALFSKIN AIRPLANE-SHAPE BAG WITH BLACK HARDWARE BY VIRGIL ABLOH | C45: 2021 | D45: =IF(C45="","",FLOOR(C45,10)) -> 2020 | E45: Christie's | F45: https://www.christies.com/en/lot/lot-6558303 | G45: LV0041.png | H45: yes | I45: yes | J45: airplane shaped | K45: 3 | L45: 2 | M45: 2 | N45: 5 | O45: 5 | P45: 5 | Q45: 1 | R45: 3 | S45: =IF(K45="","",(K45-1)/4) -> 0.5 | T45: =IF(L45="","",(L45-1)/4) -> 0.25 | U45: =IF(M45="","",(M45-1)/4) -> 0.25 | V45: =IF(N45="","",(N45-1)/4) -> 1 | W45: =IF(O45="","",(O45-1)/4) -> 1 | X45: =IF(P45="","",(P45-1)/4) -> 1 | Y45: =IF(Q45="","",(Q45-1)/4) -> 0 | Z45: =IF(R45="","",(R45-1)/4) -> 0.5 | AA45: =IF(AND(S45<>"",C45<=1949,I45="yes"),S45,"") | AB45: =IF(AND(T45<>"",C45<=1949,I45="yes"),T45,"") | AC45: =IF(AND(U45<>"",C45<=1949,I45="yes"),U45,"") | AD45: =IF(AND(V45<>"",C45<=1949,I45="yes"),V45,"") | AE45: =IF(AND(W45<>"",C45<=1949,I45="yes"),W45,"") | AF45: =IF(AND(X45<>"",C45<=1949,I45="yes"),X45,"") | AG45: =IF(AND(Y45<>"",C45<=1949,I45="yes"),Y45,"") | AH45: =IF(AND(Z45<>"",C45<=1949,I45="yes"),Z45,"") | AI45: =IF(OR(S45="",'4_BENCHMARK'!$C$4=""),"",ABS(S45-'4_BENCHMARK'!$C$4)) -> 0.5 | AJ45: =IF(OR(T45="",'4_BENCHMARK'!$C$5=""),"",ABS(T45-'4_BENCHMARK'!$C$5)) -> 0.75 | AK45: =IF(OR(U45="",'4_BENCHMARK'!$C$6=""),"",ABS(U45-'4_BENCHMARK'!$C$6)) -> 0.75 | AL45: =IF(OR(V45="",'4_BENCHMARK'!$C$7=""),"",ABS(V45-'4_BENCHMARK'!$C$7)) -> 0 | AM45: =IF(OR(W45="",'4_BENCHMARK'!$C$8=""),"",ABS(W45-'4_BENCHMARK'!$C$8)) -> 1 | AN45: =IF(OR(X45="",'4_BENCHMARK'!$C$9=""),"",ABS(X45-'4_BENCHMARK'!$C$9)) -> 1 | AO45: =IF(OR(Y45="",'4_BENCHMARK'!$C$10=""),"",ABS(Y45-'4_BENCHMARK'!$C$10)) -> 0.5 | AP45: =IF(OR(Z45="",'4_BENCHMARK'!$C$11=""),"",ABS(Z45-'4_BENCHMARK'!$C$11)) -> 0.5 | AQ45: =IF(COUNT(AI45:AP45)<8,"",1-AVERAGE(AI45:AP45)) -> 0.375 | AS45: bag | AT45: =IF(COUNT(AI45:AL45,AO45:AP45)<6,"",1-AVERAGE(AI45:AL45,AO45:AP45)) -> 0.5 | AU45: =IF(AND($I45="yes",$C45<=1949,K45<>""),K45,"") | AV45: =IF(AND($I45="yes",$C45<=1949,L45<>""),L45,"") | AW45: =IF(AND($I45="yes",$C45<=1949,M45<>""),M45,"") | AX45: =IF(AND($I45="yes",$C45<=1949,N45<>""),N45,"") | AY45: =IF(AND($I45="yes",$C45<=1949,O45<>""),O45,"") | AZ45: =IF(AND($I45="yes",$C45<=1949,P45<>""),P45,"") | BA45: =IF(AND($I45="yes",$C45<=1949,Q45<>""),Q45,"") | BB45: =IF(AND($I45="yes",$C45<=1949,R45<>""),R45,"") | BC45: =IF(AND($I45="yes",$C45>=2000,K45<>""),K45,"") -> 3 | BD45: =IF(AND($I45="yes",$C45>=2000,L45<>""),L45,"") -> 2 | BE45: =IF(AND($I45="yes",$C45>=2000,M45<>""),M45,"") -> 2 | BF45: =IF(AND($I45="yes",$C45>=2000,N45<>""),N45,"") -> 5 | BG45: =IF(AND($I45="yes",$C45>=2000,O45<>""),O45,"") -> 5 | BH45: =IF(AND($I45="yes",$C45>=2000,P45<>""),P45,"") -> 5 | BI45: =IF(AND($I45="yes",$C45>=2000,Q45<>""),Q45,"") -> 1 | BJ45: =IF(AND($I45="yes",$C45>=2000,R45<>""),R45,"") -> 3
A46: 42 | B46: A RARE, MONOGRAM CANVAS EXPLORATOR'S CAMP BED TRUNK WITH BRASS HARDWARE | C46: 1911 | D46: =IF(C46="","",FLOOR(C46,10)) -> 1910 | E46: Christie's | F46: https://onlineonly.christies.com/s/legendary-trunks-european-private-collection-part-ii/rare-monogram-canvas-explorators-camp-bed-trunk-brass-hardware-33/262983 | G46: LV0042.png | H46: no | I46: yes | K46: 5 | L46: 5 | M46: 5 | N46: 5 | O46: 5 | P46: 5 | Q46: 3 | R46: 5 | S46: =IF(K46="","",(K46-1)/4) -> 1 | T46: =IF(L46="","",(L46-1)/4) -> 1 | U46: =IF(M46="","",(M46-1)/4) -> 1 | V46: =IF(N46="","",(N46-1)/4) -> 1 | W46: =IF(O46="","",(O46-1)/4) -> 1 | X46: =IF(P46="","",(P46-1)/4) -> 1 | Y46: =IF(Q46="","",(Q46-1)/4) -> 0.5 | Z46: =IF(R46="","",(R46-1)/4) -> 1 | AA46: =IF(AND(S46<>"",C46<=1949,I46="yes"),S46,"") -> 1 | AB46: =IF(AND(T46<>"",C46<=1949,I46="yes"),T46,"") -> 1 | AC46: =IF(AND(U46<>"",C46<=1949,I46="yes"),U46,"") -> 1 | AD46: =IF(AND(V46<>"",C46<=1949,I46="yes"),V46,"") -> 1 | AE46: =IF(AND(W46<>"",C46<=1949,I46="yes"),W46,"") -> 1 | AF46: =IF(AND(X46<>"",C46<=1949,I46="yes"),X46,"") -> 1 | AG46: =IF(AND(Y46<>"",C46<=1949,I46="yes"),Y46,"") -> 0.5 | AH46: =IF(AND(Z46<>"",C46<=1949,I46="yes"),Z46,"") -> 1 | AI46: =IF(OR(S46="",'4_BENCHMARK'!$C$4=""),"",ABS(S46-'4_BENCHMARK'!$C$4)) -> 0 | AJ46: =IF(OR(T46="",'4_BENCHMARK'!$C$5=""),"",ABS(T46-'4_BENCHMARK'!$C$5)) -> 0 | AK46: =IF(OR(U46="",'4_BENCHMARK'!$C$6=""),"",ABS(U46-'4_BENCHMARK'!$C$6)) -> 0 | AL46: =IF(OR(V46="",'4_BENCHMARK'!$C$7=""),"",ABS(V46-'4_BENCHMARK'!$C$7)) -> 0 | AM46: =IF(OR(W46="",'4_BENCHMARK'!$C$8=""),"",ABS(W46-'4_BENCHMARK'!$C$8)) -> 1 | AN46: =IF(OR(X46="",'4_BENCHMARK'!$C$9=""),"",ABS(X46-'4_BENCHMARK'!$C$9)) -> 1 | AO46: =IF(OR(Y46="",'4_BENCHMARK'!$C$10=""),"",ABS(Y46-'4_BENCHMARK'!$C$10)) -> 0 | AP46: =IF(OR(Z46="",'4_BENCHMARK'!$C$11=""),"",ABS(Z46-'4_BENCHMARK'!$C$11)) -> 0 | AQ46: =IF(COUNT(AI46:AP46)<8,"",1-AVERAGE(AI46:AP46)) -> 0.75 | AS46: trunk | AT46: =IF(COUNT(AI46:AL46,AO46:AP46)<6,"",1-AVERAGE(AI46:AL46,AO46:AP46)) -> 1 | AU46: =IF(AND($I46="yes",$C46<=1949,K46<>""),K46,"") -> 5 | AV46: =IF(AND($I46="yes",$C46<=1949,L46<>""),L46,"") -> 5 | AW46: =IF(AND($I46="yes",$C46<=1949,M46<>""),M46,"") -> 5 | AX46: =IF(AND($I46="yes",$C46<=1949,N46<>""),N46,"") -> 5 | AY46: =IF(AND($I46="yes",$C46<=1949,O46<>""),O46,"") -> 5 | AZ46: =IF(AND($I46="yes",$C46<=1949,P46<>""),P46,"") -> 5 | BA46: =IF(AND($I46="yes",$C46<=1949,Q46<>""),Q46,"") -> 3 | BB46: =IF(AND($I46="yes",$C46<=1949,R46<>""),R46,"") -> 5 | BC46: =IF(AND($I46="yes",$C46>=2000,K46<>""),K46,"") | BD46: =IF(AND($I46="yes",$C46>=2000,L46<>""),L46,"") | BE46: =IF(AND($I46="yes",$C46>=2000,M46<>""),M46,"") | BF46: =IF(AND($I46="yes",$C46>=2000,N46<>""),N46,"") | BG46: =IF(AND($I46="yes",$C46>=2000,O46<>""),O46,"") | BH46: =IF(AND($I46="yes",$C46>=2000,P46<>""),P46,"") | BI46: =IF(AND($I46="yes",$C46>=2000,Q46<>""),Q46,"") | BJ46: =IF(AND($I46="yes",$C46>=2000,R46<>""),R46,"")
